Workbook

Sheet Итоги
A1: Логика Дома — финансовая модель на 3 года
A2: Сводка по годам; все цифры считаются из листов «Допущения», «Штат», «Помесячно». ₽.
A4: Показатель | B4: 1-й год | C4: 2-й год | D4: 3-й год | E4: Итого 3 года
A5: Посетители сайта | B5: =SUMIF(Помесячно!$B$4:$AK$4,1,Помесячно!$B$6:$AK$6) -> 87005.002 | C5: =SUMIF(Помесячно!$B$4:$AK$4,2,Помесячно!$B$6:$AK$6) -> 249584.11 | D5: =SUMIF(Помесячно!$B$4:$AK$4,3,Помесячно!$B$6:$AK$6) -> 410534.46 | E5: =SUM(B5:D5) -> 747123.57
A6: Сохранённые проекты | B6: =SUMIF(Помесячно!$B$4:$AK$4,1,Помесячно!$B$8:$AK$8) -> 2610.1501 | C6: =SUMIF(Помесячно!$B$4:$AK$4,2,Помесячно!$B$8:$AK$8) -> 7487.5233 | D6: =SUMIF(Помесячно!$B$4:$AK$4,3,Помесячно!$B$8:$AK$8) -> 12316.034 | E6: =SUM(B6:D6) -> 22413.707
A7: Заявки на подбор подрядчика | B7: =SUMIF(Помесячно!$B$4:$AK$4,1,Помесячно!$B$9:$AK$9) -> 652.53752 | C7: =SUMIF(Помесячно!$B$4:$AK$4,2,Помесячно!$B$9:$AK$9) -> 1871.8808 | D7: =SUMIF(Помесячно!$B$4:$AK$4,3,Помесячно!$B$9:$AK$9) -> 3079.0084 | E7: =SUM(B7:D7) -> 5603.4268
A8: Эскизные проекты PDF, шт. | B8: =SUMIF(Помесячно!$B$4:$AK$4,1,Помесячно!$B$11:$AK$11) -> 130.5075 | C8: =SUMIF(Помесячно!$B$4:$AK$4,2,Помесячно!$B$11:$AK$11) -> 374.37617 | D8: =SUMIF(Помесячно!$B$4:$AK$4,3,Помесячно!$B$11:$AK$11) -> 615.80168 | E8: =SUM(B8:D8) -> 1120.6854
A9: Файлы для ArchiCAD, шт. | B9: =SUMIF(Помесячно!$B$4:$AK$4,1,Помесячно!$B$12:$AK$12) -> 52.203001 | C9: =SUMIF(Помесячно!$B$4:$AK$4,2,Помесячно!$B$12:$AK$12) -> 149.75047 | D9: =SUMIF(Помесячно!$B$4:$AK$4,3,Помесячно!$B$12:$AK$12) -> 246.32067 | E9: =SUM(B9:D9) -> 448.27414
A10: Верификации, шт. | B10: =SUMIF(Помесячно!$B$4:$AK$4,1,Помесячно!$B$13:$AK$13) -> 39.152251 | C10: =SUMIF(Помесячно!$B$4:$AK$4,2,Помесячно!$B$13:$AK$13) -> 112.31285 | D10: =SUMIF(Помесячно!$B$4:$AK$4,3,Помесячно!$B$13:$AK$13) -> 184.74051 | E10: =SUM(B10:D10) -> 336.20561
A11: АКР, шт. | B11: =SUMIF(Помесячно!$B$4:$AK$4,1,Помесячно!$B$14:$AK$14) -> 10.4406 | C11: =SUMIF(Помесячно!$B$4:$AK$4,2,Помесячно!$B$14:$AK$14) -> 29.950093 | D11: =SUMIF(Помесячно!$B$4:$AK$4,3,Помесячно!$B$14:$AK$14) -> 49.264135 | E11: =SUM(B11:D11) -> 89.654828
A12: Сделки с СК через платформу, шт. | B12: =SUMIF(Помесячно!$B$4:$AK$4,1,Помесячно!$B$19:$AK$19) -> 19.576125 | C12: =SUMIF(Помесячно!$B$4:$AK$4,2,Помесячно!$B$19:$AK$19) -> 56.156425 | D12: =SUMIF(Помесячно!$B$4:$AK$4,3,Помесячно!$B$19:$AK$19) -> 92.370253 | E12: =SUM(B12:D12) -> 168.1028
A13: Выручка
A14: Эскизные проекты PDF | B14: =SUMIF(Помесячно!$B$4:$AK$4,1,Помесячно!$B$21:$AK$21) -> 391522.51 | C14: =SUMIF(Помесячно!$B$4:$AK$4,2,Помесячно!$B$21:$AK$21) -> 1123128.5 | D14: =SUMIF(Помесячно!$B$4:$AK$4,3,Помесячно!$B$21:$AK$21) -> 1847405.1 | E14: =SUM(B14:D14) -> 3362056.1
A15: Файлы для ArchiCAD | B15: =SUMIF(Помесячно!$B$4:$AK$4,1,Помесячно!$B$22:$AK$22) -> 156609 | C15: =SUMIF(Помесячно!$B$4:$AK$4,2,Помесячно!$B$22:$AK$22) -> 449251.4 | D15: =SUMIF(Помесячно!$B$4:$AK$4,3,Помесячно!$B$22:$AK$22) -> 738962.02 | E15: =SUM(B15:D15) -> 1344822.4
A16: Верификация | B16: =SUMIF(Помесячно!$B$4:$AK$4,1,Помесячно!$B$23:$AK$23) -> 587283.76 | C16: =SUMIF(Помесячно!$B$4:$AK$4,2,Помесячно!$B$23:$AK$23) -> 1684692.7 | D16: =SUMIF(Помесячно!$B$4:$AK$4,3,Помесячно!$B$23:$AK$23) -> 2771107.6 | E16: =SUM(B16:D16) -> 5043084.1
A17: АКР | B17: =SUMIF(Помесячно!$B$4:$AK$4,1,Помесячно!$B$24:$AK$24) -> 783045.02 | C17: =SUMIF(Помесячно!$B$4:$AK$4,2,Помесячно!$B$24:$AK$24) -> 2246257 | D17: =SUMIF(Помесячно!$B$4:$AK$4,3,Помесячно!$B$24:$AK$24) -> 3694810.1 | E17: =SUM(B17:D17) -> 6724112.1
A18: Визуализации | B18: =SUMIF(Помесячно!$B$4:$AK$4,1,Помесячно!$B$25:$AK$25) -> 46982.701 | C18: =SUMIF(Помесячно!$B$4:$AK$4,2,Помесячно!$B$25:$AK$25) -> 134775.42 | D18: =SUMIF(Помесячно!$B$4:$AK$4,3,Помесячно!$B$25:$AK$25) -> 221688.61 | E18: =SUM(B18:D18) -> 403446.73
A19: Рассылка и отчёт | B19: =SUMIF(Помесячно!$B$4:$AK$4,1,Помесячно!$B$26:$AK$26) -> 293641.88 | C19: =SUMIF(Помесячно!$B$4:$AK$4,2,Помесячно!$B$26:$AK$26) -> 842346.37 | D19: =SUMIF(Помесячно!$B$4:$AK$4,3,Помесячно!$B$26:$AK$26) -> 1385553.8 | E19: =SUM(B19:D19) -> 2521542
A20: Полное сопровождение | B20: =SUMIF(Помесячно!$B$4:$AK$4,1,Помесячно!$B$27:$AK$27) -> 777824.72 | C20: =SUMIF(Помесячно!$B$4:$AK$4,2,Помесячно!$B$27:$AK$27) -> 2231281.9 | D20: =SUMIF(Помесячно!$B$4:$AK$4,3,Помесячно!$B$27:$AK$27) -> 3670178 | E20: =SUM(B20:D20) -> 6679284.7
A21: Продажа заявок СК | B21: =SUMIF(Помесячно!$B$4:$AK$4,1,Помесячно!$B$28:$AK$28) -> 652537.52 | C21: =SUMIF(Помесячно!$B$4:$AK$4,2,Помесячно!$B$28:$AK$28) -> 1871880.8 | D21: =SUMIF(Помесячно!$B$4:$AK$4,3,Помесячно!$B$28:$AK$28) -> 3079008.4 | E21: =SUM(B21:D21) -> 5603426.8
A22: Вознаграждение за горячих клиентов | B22: =SUMIF(Помесячно!$B$4:$AK$4,1,Помесячно!$B$29:$AK$29) -> 2740657.6 | C22: =SUMIF(Помесячно!$B$4:$AK$4,2,Помесячно!$B$29:$AK$29) -> 7861899.5 | D22: =SUMIF(Помесячно!$B$4:$AK$4,3,Помесячно!$B$29:$AK$29) -> 12931835 | E22: =SUM(B22:D22) -> 23534392
A23: Выручка всего | B23: =SUMIF(Помесячно!$B$4:$AK$4,1,Помесячно!$B$30:$AK$30) -> 6430104.7 | C23: =SUMIF(Помесячно!$B$4:$AK$4,2,Помесячно!$B$30:$AK$30) -> 18445514 | D23: =SUMIF(Помесячно!$B$4:$AK$4,3,Помесячно!$B$30:$AK$30) -> 30340549 | E23: =SUM(B23:D23) -> 55216167
A24: Расходы
A25: Архитекторы и конструкторы по заказам | B25: =SUMIF(Помесячно!$B$4:$AK$4,1,Помесячно!$B$32:$AK$32) -> 763468.89 | C25: =SUMIF(Помесячно!$B$4:$AK$4,2,Помесячно!$B$32:$AK$32) -> 1684692.7 | D25: =SUMIF(Помесячно!$B$4:$AK$4,3,Помесячно!$B$32:$AK$32) -> 2771107.6 | E25: =SUM(B25:D25) -> 5219269.2
A26: API визуализаций | B26: =SUMIF(Помесячно!$B$4:$AK$4,1,Помесячно!$B$33:$AK$33) -> 6264.3602 | C26: =SUMIF(Помесячно!$B$4:$AK$4,2,Помесячно!$B$33:$AK$33) -> 17970.056 | D26: =SUMIF(Помесячно!$B$4:$AK$4,3,Помесячно!$B$33:$AK$33) -> 29558.481 | E26: =SUM(B26:D26) -> 53792.897
A27: Эквайринг | B27: =SUMIF(Помесячно!$B$4:$AK$4,1,Помесячно!$B$34:$AK$34) -> 91107.288 | C27: =SUMIF(Помесячно!$B$4:$AK$4,2,Помесячно!$B$34:$AK$34) -> 261352 | D27: =SUMIF(Помесячно!$B$4:$AK$4,3,Помесячно!$B$34:$AK$34) -> 429891.16 | E27: =SUM(B27:D27) -> 782350.45
A28: Налог УСН 6 % | B28: =SUMIF(Помесячно!$B$4:$AK$4,1,Помесячно!$B$35:$AK$35) -> 385806.28 | C28: =SUMIF(Помесячно!$B$4:$AK$4,2,Помесячно!$B$35:$AK$35) -> 1106730.8 | D28: =SUMIF(Помесячно!$B$4:$AK$4,3,Помесячно!$B$35:$AK$35) -> 1820432.9 | E28: =SUM(B28:D28) -> 3312970
A29: Зарплата с взносами | B29: =SUMIF(Помесячно!$B$4:$AK$4,1,Помесячно!$B$36:$AK$36) -> 3588000 | C29: =SUMIF(Помесячно!$B$4:$AK$4,2,Помесячно!$B$36:$AK$36) -> 7644000 | D29: =SUMIF(Помесячно!$B$4:$AK$4,3,Помесячно!$B$36:$AK$36) -> 11076000 | E29: =SUM(B29:D29) -> 22308000
A30: Маркетинг | B30: =SUMIF(Помесячно!$B$4:$AK$4,1,Помесячно!$B$37:$AK$37) -> 1800000 | C30: =SUMIF(Помесячно!$B$4:$AK$4,2,Помесячно!$B$37:$AK$37) -> 3600000 | D30: =SUMIF(Помесячно!$B$4:$AK$4,3,Помесячно!$B$37:$AK$37) -> 4800000 | E30: =SUM(B30:D30) -> 10200000
A31: Сервер, сервисы, прочее | B31: =SUMIF(Помесячно!$B$4:$AK$4,1,Помесячно!$B$38:$AK$38) -> 660000 | C31: =SUMIF(Помесячно!$B$4:$AK$4,2,Помесячно!$B$38:$AK$38) -> 660000 | D31: =SUMIF(Помесячно!$B$4:$AK$4,3,Помесячно!$B$38:$AK$38) -> 660000 | E31: =SUM(B31:D31) -> 1980000
A32: Расходы всего | B32: =SUMIF(Помесячно!$B$4:$AK$4,1,Помесячно!$B$39:$AK$39) -> 7294646.8 | C32: =SUMIF(Помесячно!$B$4:$AK$4,2,Помесячно!$B$39:$AK$39) -> 14974746 | D32: =SUMIF(Помесячно!$B$4:$AK$4,3,Помесячно!$B$39:$AK$39) -> 21586990 | E32: =SUM(B32:D32) -> 43856383
A33: Прибыль (убыток) | B33: =SUMIF(Помесячно!$B$4:$AK$4,1,Помесячно!$B$40:$AK$40) -> -864542.14 | C33: =SUMIF(Помесячно!$B$4:$AK$4,2,Помесячно!$B$40:$AK$40) -> 3470768.1 | D33: =SUMIF(Помесячно!$B$4:$AK$4,3,Помесячно!$B$40:$AK$40) -> 8753558.8 | E33: =SUM(B33:D33) -> 11359785
A34: Рентабельность по прибыли | B34: =IF(B23=0,0,B33/B23) -> -0.13445227 | C34: =IF(C23=0,0,C33/C23) -> 0.18816326 | D34: =IF(D23=0,0,D33/D23) -> 0.28851023 | E34: =IF(E23=0,0,E33/E23) -> 0.20573295
A35: Накопленный результат на конец года | B35: =INDEX(Помесячно!$B$41:$AK$41,12) -> -864542.14 | C35: =INDEX(Помесячно!$B$41:$AK$41,24) -> 2606225.9 | D35: =INDEX(Помесячно!$B$41:$AK$41,36) -> 11359785
A36: Человек в штате | B36: =Штат!C10 -> 3 | C36: =Штат!D10 -> 6.5 | D36: =Штат!E10 -> 9
A37: Максимальная потребность в деньгах (самый глубокий минус) | E37: =-MIN(0,MIN(Помесячно!$B$41:$AK$41)) -> 1578610.4
A38: Месяц выхода в плюс по накопленному результату | E38: =IFERROR(INDEX(Помесячно!$B$3:$AK$3,MATCH(1,INDEX((Помесячно!$B$41:$AK$41>0)*(Помесячно!$B$3:$AK$3>=MATCH(MIN(Помесячно!$B$41:$AK$41),Помесячно!$B$41:$AK$41,0)),0),0)),"после 36-го") -> 20
A40: Как читать: синие числа на листе «Допущения» и «Штат» — оценки модели, их нужно уточнять по фактической статистике (Метрика, CRM). Жёлтые — сильнее всего влияют на результат.
A41: Главный рычаг дохода — сделки с СК через платформу (2 % стоимости дома) и АКР; платные выгрузки и отчёты окупают маркетинг и дают поток клиентов.
A42: Налог: ИП на УСН «доходы» 6 %. Не учтён 1 % взносов с дохода свыше 300 тыс. ₽ (до лимита) — его можно уменьшить налог по правилам УСН.
...

Sheet Допущения
A1: Финансовая модель «Логика Дома» на 3 года — допущения
A2: Синие числа — допущения, их можно менять; жёлтые — ключевые. Все остальные листы считаются формулами.
A4: Трафик и спрос
A5: Посетителей сайта в 1-й месяц | B5: 3000 | C5: Старт: SEO-страницы проектов, статьи, соцсети, реклама. Оценка модели — уточняйте по Метрике.
A6: Рост посетителей в месяц, 1-й год | B6: 0.15 | C6: Быстрый рост на старте за счёт рекламы и SEO.
A7: Рост посетителей в месяц, 2-й год | B7: 0.06 | C7: Оценка модели.
A8: Рост посетителей в месяц, 3-й год | B8: 0.03 | C8: Оценка модели; выход в соседние регионы.
A9: Доля посетителей, работающих в конструкторе | B9: 0.3 | C9: Конструктор — главная точка входа на сайт.
A10: Доля сохранивших проект (регистрация) | B10: 0.1 | C10: Из работавших в конструкторе.
A11: Доля оставивших заявку на подбор подрядчика | B11: 0.025 | C11: Из работавших в конструкторе.
A12: Конверсия в платные услуги (из сохранивших проект)
A13: Покупают эскизный проект PDF | B13: 0.05 | C13: Оценка модели.
A14: Покупают файлы для ArchiCAD | B14: 0.02 | C14: В основном архитекторы и те, у кого свой архитектор.
A15: Заказывают верификацию | B15: 0.015 | C15: Оценка модели.
A16: Заказывают АКР | B16: 0.004 | C16: Оценка модели; часть — после верификации.
A17: Покупают пакет визуализаций | B17: 0.04 | C17: Оценка модели.
A18: Заявки на подбор подрядчика
A19: Выбирают «Рассылка и отчёт» | B19: 0.3 | C19: Из заявок.
A20: Выбирают «Полное сопровождение» | B20: 0.08 | C20: Из заявок.
A21: Заявки, проданные строительным компаниям | B21: 0.4 | C21: Контакты по услуге «рассылка и отчёт» и бесплатные обращения — по сетке цен.
A22: Сделки с СК через платформу («горячий клиент») | B22: 0.03 | C22: Из заявок: созвон, согласованная цена, договор.
A23: Цены, ₽ (по сайту)
A24: Эскизный проект PDF | B24: 3000 | C24: Цена с сайта (решение владельца).
A25: Файлы для ArchiCAD | B25: 3000 | C25: Цена с сайта (решение владельца).
A26: Верификация | B26: 15000 | C26: Цена с сайта.
A27: АКР, средний чек | B27: 75000 | C27: На сайте «от 50 000 ₽»; средний чек — оценка модели.
A28: Пакет визуализаций, средний чек | B28: 450 | C28: Пакет «10 за 450 ₽».
A29: Рассылка и отчёт | B29: 1500 | C29: Цена с сайта (решение владельца).
A30: Полное сопровождение | B30: 14900 | C30: Цена с сайта; СК компенсирует клиенту при договоре.
A31: Цена заявки для СК, средняя | B31: 2500 | C31: По сетке цены лида в CRM — уточните.
A32: Средняя стоимость домовладения | B32: 7000000 | C32: Оценка модели для Перми.
A33: Вознаграждение за горячего клиента | B33: 0.02 | C33: Оферта для компаний: 2 % стоимости домовладения.
A34: Переменные расходы
A35: Архитектор за верификацию, доля цены | B35: 0.5 | C35: Если архитектор не в штате — по договору.
A36: Архитектор и конструктор за АКР, доля цены | B36: 0.6 | C36: Оценка модели.
A37: Себестоимость пакета визуализаций (API «Пользы») | B37: 60 | C37: ≈ 4–6 ₽ за генерацию × 10 с учётом повторов.
A38: Эквайринг, доля оплат клиентов | B38: 0.03 | C38: ЮKassa / Т-Банк: 2,5–3,5 %.
A39: Налог УСН «доходы» | B39: 0.06 | C39: ИП на УСН 6 %; взносы ИП за себя — в постоянных расходах.
A40: Постоянные расходы, ₽ в месяц
A41: Сервер, домен, резервные копии | B41: 15000 | C41: VPS в России + хранение файлов.
...

Sheet Штат
A1: Штат и зарплаты (до вычета НДФЛ, ₽ в месяц); численность — по годам
A3: Роль | B3: Оклад, ₽/мес | C3: 1-й год | D3: 2-й год | E3: 3-й год | F3: Что делает
A4: Менеджер по клиентам | B4: 70000 | C4: 1 | D4: 2 | E4: 3 | F4: Заявки, созвоны, отчёты, полное сопровождение, договоры с СК
A5: Сметчик | B5: 60000 | C5: 0.5 | D5: 1 | E5: 1 | F5: Расчёты, сравнение смет и технологий
A6: Маркетолог | B6: 70000 | C6: 1 | D6: 1 | E6: 1 | F6: Контент, SEO, реклама, соцсети
A7: Архитектор (в штате) | B7: 90000 | C7: 0 | D7: 1 | E7: 2 | F7: Верификация, правки, посадка на участок; с 2-го года вместо подряда
A8: Разработчик (поддержка сайта) | B8: 120000 | C8: 0.5 | D8: 0.5 | E8: 1 | F8: Доработки и поддержка платформы
A9: Менеджер по работе с СК | B9: 70000 | C9: 0 | D9: 1 | E9: 1 | F9: Подключение компаний, оплата заявок
A10: Человек в штате | C10: =SUM(C4:C9) -> 3 | D10: =SUM(D4:D9) -> 6.5 | E10: =SUM(E4:E9) -> 9
A11: Фонд оплаты с взносами, ₽ в месяц | C11: =SUMPRODUCT($B$4:$B$9,C4:C9)*(1+Допущения!$B$48) -> 299000 | D11: =SUMPRODUCT($B$4:$B$9,D4:D9)*(1+Допущения!$B$48) -> 637000 | E11: =SUMPRODUCT($B$4:$B$9,E4:E9)*(1+Допущения!$B$48) -> 923000
A13: Доля ставки 0,5 — частичная занятость или совмещение. Владелец (ИП) в штат не включён: его доход — прибыль.

Sheet Помесячно
A1: Помесячный расчёт, 36 месяцев (₽)
A3: Месяц | B3: 1 | C3: 2 | D3: 3 | E3: 4 | F3: 5 | G3: 6 | H3: 7 | I3: 8 | J3: 9 | K3: 10 | L3: 11 | M3: 12 | N3: 13 | O3: 14 | P3: 15 | Q3: 16 | R3: 17 | S3: 18 | T3: 19 | U3: 20 | V3: 21 | W3: 22 | X3: 23 | Y3: 24 | Z3: 25 | AA3: 26 | AB3: 27 | AC3: 28 | AD3: 29 | AE3: 30 | AF3: 31 | AG3: 32 | AH3: 33 | AI3: 34 | AJ3: 35 | AK3: 36
A4: Год | B4: =INT((B3-1)/12)+1 -> 1 | C4: =INT((C3-1)/12)+1 -> 1 | D4: =INT((D3-1)/12)+1 -> 1 | E4: =INT((E3-1)/12)+1 -> 1 | F4: =INT((F3-1)/12)+1 -> 1 | G4: =INT((G3-1)/12)+1 -> 1 | H4: =INT((H3-1)/12)+1 -> 1 | I4: =INT((I3-1)/12)+1 -> 1 | ... AK4: =INT((AK3-1)/12)+1 -> 3
A5: Спрос
A6: Посетители | B6: =Допущения!$B$5 -> 3000 | C6: =B6*(1+CHOOSE(C4,Допущения!$B$6,Допущения!$B$7,Допущения!$B$8)) -> 3450 | D6: =C6*(1+CHOOSE(D4,Допущения!$B$6,Допущения!$B$7,Допущения!$B$8)) -> 3967.5 | E6: =D6*(1+CHOOSE(E4,Допущения!$B$6,Допущения!$B$7,Допущения!$B$8)) -> 4562.625 | F6: =E6*(1+CHOOSE(F4,Допущения!$B$6,Допущения!$B$7,Допущения!$B$8)) -> 5247.0188 | G6: =F6*(1+CHOOSE(G4,Допущения!$B$6,Допущения!$B$7,Допущения!$B$8)) -> 6034.0716 | H6: =G6*(1+CHOOSE(H4,Допущения!$B$6,Допущения!$B$7,Допущения!$B$8)) -> 6939.1823 | I6: =H6*(1+CHOOSE(I4,Допущения!$B$6,Допущения!$B$7,Допущения!$B$8)) -> 7980.0596 | J6: =I6*(1+CHOOSE(J4,Допущения!$B$6,Допущения!$B$7,Допущения!$B$8)) -> 9177.0686 | ... AK6: =AJ6*(1+CHOOSE(AK4,Допущения!$B$6,Допущения!$B$7,Допущения!$B$8)) -> 40041.891
A7: Работали в конструкторе | B7: =B6*Допущения!$B$9 -> 900 | C7: =C6*Допущения!$B$9 -> 1035 | D7: =D6*Допущения!$B$9 -> 1190.25 | E7: =E6*Допущения!$B$9 -> 1368.7875 | F7: =F6*Допущения!$B$9 -> 1574.1056 | G7: =G6*Допущения!$B$9 -> 1810.2215 | H7: =H6*Допущения!$B$9 -> 2081.7547 | I7: =I6*Допущения!$B$9 -> 2394.0179 | ... AK7: =AK6*Допущения!$B$9 -> 12012.567
A8: Сохранили проект | B8: =B7*Допущения!$B$10 -> 90 | C8: =C7*Допущения!$B$10 -> 103.5 | D8: =D7*Допущения!$B$10 -> 119.025 | E8: =E7*Допущения!$B$10 -> 136.87875 | F8: =F7*Допущения!$B$10 -> 157.41056 | G8: =G7*Допущения!$B$10 -> 181.02215 | H8: =H7*Допущения!$B$10 -> 208.17547 | I8: =I7*Допущения!$B$10 -> 239.40179 | ... AK8: =AK7*Допущения!$B$10 -> 1201.2567
A9: Заявки на подбор подрядчика | B9: =B7*Допущения!$B$11 -> 22.5 | C9: =C7*Допущения!$B$11 -> 25.875 | D9: =D7*Допущения!$B$11 -> 29.75625 | E9: =E7*Допущения!$B$11 -> 34.219687 | F9: =F7*Допущения!$B$11 -> 39.352641 | G9: =G7*Допущения!$B$11 -> 45.255537 | H9: =H7*Допущения!$B$11 -> 52.043867 | I9: =I7*Допущения!$B$11 -> 59.850447 | ... AK9: =AK7*Допущения!$B$11 -> 300.31418
A10: Продажи, шт.
A11: Эскизные проекты PDF | B11: =B8*Допущения!$B$13 -> 4.5 | C11: =C8*Допущения!$B$13 -> 5.175 | D11: =D8*Допущения!$B$13 -> 5.95125 | E11: =E8*Допущения!$B$13 -> 6.8439375 | F11: =F8*Допущения!$B$13 -> 7.8705281 | G11: =G8*Допущения!$B$13 -> 9.0511073 | H11: =H8*Допущения!$B$13 -> 10.408773 | I11: =I8*Допущения!$B$13 -> 11.970089 | ... AK11: =AK8*Допущения!$B$13 -> 60.062836
A12: Файлы для ArchiCAD | B12: =B8*Допущения!$B$14 -> 1.8 | C12: =C8*Допущения!$B$14 -> 2.07 | D12: =D8*Допущения!$B$14 -> 2.3805 | E12: =E8*Допущения!$B$14 -> 2.737575 | F12: =F8*Допущения!$B$14 -> 3.1482113 | G12: =G8*Допущения!$B$14 -> 3.6204429 | H12: =H8*Допущения!$B$14 -> 4.1635094 | I12: =I8*Допущения!$B$14 -> 4.7880358 | ... AK12: =AK8*Допущения!$B$14 -> 24.025135
A13: Верификации | B13: =B8*Допущения!$B$15 -> 1.35 | C13: =C8*Допущения!$B$15 -> 1.5525 | D13: =D8*Допущения!$B$15 -> 1.785375 | E13: =E8*Допущения!$B$15 -> 2.0531813 | F13: =F8*Допущения!$B$15 -> 2.3611584 | G13: =G8*Допущения!$B$15 -> 2.7153322 | H13: =H8*Допущения!$B$15 -> 3.122632 | I13: =I8*Допущения!$B$15 -> 3.5910268 | ... AK13: =AK8*Допущения!$B$15 -> 18.018851
A14: АКР | B14: =B8*Допущения!$B$16 -> 0.36 | C14: =C8*Допущения!$B$16 -> 0.414 | D14: =D8*Допущения!$B$16 -> 0.4761 | E14: =E8*Допущения!$B$16 -> 0.547515 | F14: =F8*Допущения!$B$16 -> 0.62964225 | G14: =G8*Допущения!$B$16 -> 0.72408859 | H14: =H8*Допущения!$B$16 -> 0.83270188 | I14: =I8*Допущения!$B$16 -> 0.95760716 | ... AK14: =AK8*Допущения!$B$16 -> 4.8050269
A15: Пакеты визуализаций | B15: =B8*Допущения!$B$17 -> 3.6 | C15: =C8*Допущения!$B$17 -> 4.14 | D15: =D8*Допущения!$B$17 -> 4.761 | E15: =E8*Допущения!$B$17 -> 5.47515 | F15: =F8*Допущения!$B$17 -> 6.2964225 | G15: =G8*Допущения!$B$17 -> 7.2408859 | H15: =H8*Допущения!$B$17 -> 8.3270188 | I15: =I8*Допущения!$B$17 -> 9.5760716 | ... AK15: =AK8*Допущения!$B$17 -> 48.050269
A16: Рассылка и отчёт | B16: =B9*Допущения!$B$19 -> 6.75 | C16: =C9*Допущения!$B$19 -> 7.7625 | D16: =D9*Допущения!$B$19 -> 8.926875 | E16: =E9*Допущения!$B$19 -> 10.265906 | F16: =F9*Допущения!$B$19 -> 11.805792 | G16: =G9*Допущения!$B$19 -> 13.576661 | H16: =H9*Допущения!$B$19 -> 15.61316 | I16: =I9*Допущения!$B$19 -> 17.955134 | ... AK16: =AK9*Допущения!$B$19 -> 90.094255
A17: Полное сопровождение | B17: =B9*Допущения!$B$20 -> 1.8 | C17: =C9*Допущения!$B$20 -> 2.07 | D17: =D9*Допущения!$B$20 -> 2.3805 | E17: =E9*Допущения!$B$20 -> 2.737575 | F17: =F9*Допущения!$B$20 -> 3.1482113 | G17: =G9*Допущения!$B$20 -> 3.6204429 | H17: =H9*Допущения!$B$20 -> 4.1635094 | I17: =I9*Допущения!$B$20 -> 4.7880358 | ... AK17: =AK9*Допущения!$B$20 -> 24.025135
A18: Заявки, проданные СК | B18: =B9*Допущения!$B$21 -> 9 | C18: =C9*Допущения!$B$21 -> 10.35 | D18: =D9*Допущения!$B$21 -> 11.9025 | E18: =E9*Допущения!$B$21 -> 13.687875 | F18: =F9*Допущения!$B$21 -> 15.741056 | G18: =G9*Допущения!$B$21 -> 18.102215 | H18: =H9*Допущения!$B$21 -> 20.817547 | I18: =I9*Допущения!$B$21 -> 23.940179 | ... AK18: =AK9*Допущения!$B$21 -> 120.12567
A19: Сделки с СК (горячие клиенты) | B19: =B9*Допущения!$B$22 -> 0.675 | C19: =C9*Допущения!$B$22 -> 0.77625 | D19: =D9*Допущения!$B$22 -> 0.8926875 | E19: =E9*Допущения!$B$22 -> 1.0265906 | F19: =F9*Допущения!$B$22 -> 1.1805792 | G19: =G9*Допущения!$B$22 -> 1.3576661 | H19: =H9*Допущения!$B$22 -> 1.561316 | I19: =I9*Допущения!$B$22 -> 1.7955134 | ... AK19: =AK9*Допущения!$B$22 -> 9.0094255
A20: Выручка, ₽
A21: Эскизные проекты PDF | B21: =B11*Допущения!$B$24 -> 13500 | C21: =C11*Допущения!$B$24 -> 15525 | D21: =D11*Допущения!$B$24 -> 17853.75 | E21: =E11*Допущения!$B$24 -> 20531.812 | F21: =F11*Допущения!$B$24 -> 23611.584 | G21: =G11*Допущения!$B$24 -> 27153.322 | H21: =H11*Допущения!$B$24 -> 31226.32 | I21: =I11*Допущения!$B$24 -> 35910.268 | ... AK21: =AK11*Допущения!$B$24 -> 180188.51
A22: Файлы для ArchiCAD | B22: =B12*Допущения!$B$25 -> 5400 | C22: =C12*Допущения!$B$25 -> 6210 | D22: =D12*Допущения!$B$25 -> 7141.5 | E22: =E12*Допущения!$B$25 -> 8212.725 | F22: =F12*Допущения!$B$25 -> 9444.6338 | G22: =G12*Допущения!$B$25 -> 10861.329 | H22: =H12*Допущения!$B$25 -> 12490.528 | I22: =I12*Допущения!$B$25 -> 14364.107 | ... AK22: =AK12*Допущения!$B$25 -> 72075.404
A23: Верификация | B23: =B13*Допущения!$B$26 -> 20250 | C23: =C13*Допущения!$B$26 -> 23287.5 | D23: =D13*Допущения!$B$26 -> 26780.625 | E23: =E13*Допущения!$B$26 -> 30797.719 | F23: =F13*Допущения!$B$26 -> 35417.377 | G23: =G13*Допущения!$B$26 -> 40729.983 | H23: =H13*Допущения!$B$26 -> 46839.481 | I23: =I13*Допущения!$B$26 -> 53865.403 | ... AK23: =AK13*Допущения!$B$26 -> 270282.76
A24: АКР | B24: =B14*Допущения!$B$27 -> 27000 | C24: =C14*Допущения!$B$27 -> 31050 | D24: =D14*Допущения!$B$27 -> 35707.5 | E24: =E14*Допущения!$B$27 -> 41063.625 | F24: =F14*Допущения!$B$27 -> 47223.169 | G24: =G14*Допущения!$B$27 -> 54306.644 | H24: =H14*Допущения!$B$27 -> 62452.641 | I24: =I14*Допущения!$B$27 -> 71820.537 | ... AK24: =AK14*Допущения!$B$27 -> 360377.02
A25: Визуализации | B25: =B15*Допущения!$B$28 -> 1620 | C25: =C15*Допущения!$B$28 -> 1863 | D25: =D15*Допущения!$B$28 -> 2142.45 | E25: =E15*Допущения!$B$28 -> 2463.8175 | F25: =F15*Допущения!$B$28 -> 2833.3901 | G25: =G15*Допущения!$B$28 -> 3258.3986 | H25: =H15*Допущения!$B$28 -> 3747.1584 | I25: =I15*Допущения!$B$28 -> 4309.2322 | ... AK25: =AK15*Допущения!$B$28 -> 21622.621
A26: Рассылка и отчёт | B26: =B16*Допущения!$B$29 -> 10125 | C26: =C16*Допущения!$B$29 -> 11643.75 | D26: =D16*Допущения!$B$29 -> 13390.312 | E26: =E16*Допущения!$B$29 -> 15398.859 | F26: =F16*Допущения!$B$29 -> 17708.688 | G26: =G16*Допущения!$B$29 -> 20364.992 | H26: =H16*Допущения!$B$29 -> 23419.74 | I26: =I16*Допущения!$B$29 -> 26932.701 | ... AK26: =AK16*Допущения!$B$29 -> 135141.38
A27: Полное сопровождение | B27: =B17*Допущения!$B$30 -> 26820 | C27: =C17*Допущения!$B$30 -> 30843 | D27: =D17*Допущения!$B$30 -> 35469.45 | E27: =E17*Допущения!$B$30 -> 40789.868 | F27: =F17*Допущения!$B$30 -> 46908.348 | G27: =G17*Допущения!$B$30 -> 53944.6 | H27: =H17*Допущения!$B$30 -> 62036.29 | I27: =I17*Допущения!$B$30 -> 71341.733 | ... AK27: =AK17*Допущения!$B$30 -> 357974.5
A28: Продажа заявок СК | B28: =B18*Допущения!$B$31 -> 22500 | C28: =C18*Допущения!$B$31 -> 25875 | D28: =D18*Допущения!$B$31 -> 29756.25 | E28: =E18*Допущения!$B$31 -> 34219.688 | F28: =F18*Допущения!$B$31 -> 39352.641 | G28: =G18*Допущения!$B$31 -> 45255.537 | H28: =H18*Допущения!$B$31 -> 52043.867 | I28: =I18*Допущения!$B$31 -> 59850.447 | ... AK28: =AK18*Допущения!$B$31 -> 300314.18
A29: Вознаграждение за горячих клиентов | B29: =B19*Допущения!$B$32*Допущения!$B$33 -> 94500 | C29: =C19*Допущения!$B$32*Допущения!$B$33 -> 108675 | D29: =D19*Допущения!$B$32*Допущения!$B$33 -> 124976.25 | E29: =E19*Допущения!$B$32*Допущения!$B$33 -> 143722.69 | F29: =F19*Допущения!$B$32*Допущения!$B$33 -> 165281.09 | G29: =G19*Допущения!$B$32*Допущения!$B$33 -> 190073.25 | H29: =H19*Допущения!$B$32*Допущения!$B$33 -> 218584.24 | I29: =I19*Допущения!$B$32*Допущения!$B$33 -> 251371.88 | ... AK29: =AK19*Допущения!$B$32*Допущения!$B$33 -> 1261319.6
A30: Выручка всего | B30: =SUM(B21:B29) -> 221715 | C30: =SUM(C21:C29) -> 254972.25 | D30: =SUM(D21:D29) -> 293218.09 | E30: =SUM(E21:E29) -> 337200.8 | F30: =SUM(F21:F29) -> 387780.92 | G30: =SUM(G21:G29) -> 445948.06 | H30: =SUM(H21:H29) -> 512840.27 | I30: =SUM(I21:I29) -> 589766.31 | ... AK30: =SUM(AK21:AK29) -> 2959295.9
A31: Расходы, ₽
A32: Архитекторы и конструкторы по заказам | B32: =B23*Допущения!$B$35*IF(B4=1,1,0.4)+B24*Допущения!$B$36 -> 26325 | C32: =C23*Допущения!$B$35*IF(C4=1,1,0.4)+C24*Допущения!$B$36 -> 30273.75 | D32: =D23*Допущения!$B$35*IF(D4=1,1,0.4)+D24*Допущения!$B$36 -> 34814.812 | E32: =E23*Допущения!$B$35*IF(E4=1,1,0.4)+E24*Допущения!$B$36 -> 40037.034 | F32: =F23*Допущения!$B$35*IF(F4=1,1,0.4)+F24*Допущения!$B$36 -> 46042.59 | G32: =G23*Допущения!$B$35*IF(G4=1,1,0.4)+G24*Допущения!$B$36 -> 52948.978 | H32: =H23*Допущения!$B$35*IF(H4=1,1,0.4)+H24*Допущения!$B$36 -> 60891.325 | I32: =I23*Допущения!$B$35*IF(I4=1,1,0.4)+I24*Допущения!$B$36 -> 70025.023 | ... AK32: =AK23*Допущения!$B$35*IF(AK4=1,1,0.4)+AK24*Допущения!$B$36 -> 270282.76
A33: API визуализаций | B33: =B15*Допущения!$B$37 -> 216 | C33: =C15*Допущения!$B$37 -> 248.4 | D33: =D15*Допущения!$B$37 -> 285.66 | E33: =E15*Допущения!$B$37 -> 328.509 | F33: =F15*Допущения!$B$37 -> 377.78535 | G33: =G15*Допущения!$B$37 -> 434.45315 | H33: =H15*Допущения!$B$37 -> 499.62113 | I33: =I15*Допущения!$B$37 -> 574.56429 | ... AK33: =AK15*Допущения!$B$37 -> 2883.0161
A34: Эквайринг | B34: =SUM(B21:B27)*Допущения!$B$38 -> 3141.45 | C34: =SUM(C21:C27)*Допущения!$B$38 -> 3612.6675 | D34: =SUM(D21:D27)*Допущения!$B$38 -> 4154.5676 | E34: =SUM(E21:E27)*Допущения!$B$38 -> 4777.7528 | F34: =SUM(F21:F27)*Допущения!$B$38 -> 5494.4157 | G34: =SUM(G21:G27)*Допущения!$B$38 -> 6318.578 | H34: =SUM(H21:H27)*Допущения!$B$38 -> 7266.3647 | I34: =SUM(I21:I27)*Допущения!$B$38 -> 8356.3195 | ... AK34: =SUM(AK21:AK27)*Допущения!$B$38 -> 41929.866
A35: Налог УСН | B35: =B30*Допущения!$B$39 -> 13302.9 | C35: =C30*Допущения!$B$39 -> 15298.335 | D35: =D30*Допущения!$B$39 -> 17593.085 | E35: =E30*Допущения!$B$39 -> 20232.048 | F35: =F30*Допущения!$B$39 -> 23266.855 | G35: =G30*Допущения!$B$39 -> 26756.884 | H35: =H30*Допущения!$B$39 -> 30770.416 | I35: =I30*Допущения!$B$39 -> 35385.978 | ... AK35: =AK30*Допущения!$B$39 -> 177557.76
A36: Зарплата с взносами | B36: =CHOOSE(B4,Штат!$C$11,Штат!$D$11,Штат!$E$11) -> 299000 | C36: =CHOOSE(C4,Штат!$C$11,Штат!$D$11,Штат!$E$11) -> 299000 | D36: =CHOOSE(D4,Штат!$C$11,Штат!$D$11,Штат!$E$11) -> 299000 | E36: =CHOOSE(E4,Штат!$C$11,Штат!$D$11,Штат!$E$11) -> 299000 | F36: =CHOOSE(F4,Штат!$C$11,Штат!$D$11,Штат!$E$11) -> 299000 | G36: =CHOOSE(G4,Штат!$C$11,Штат!$D$11,Штат!$E$11) -> 299000 | H36: =CHOOSE(H4,Штат!$C$11,Штат!$D$11,Штат!$E$11) -> 299000 | I36: =CHOOSE(I4,Штат!$C$11,Штат!$D$11,Штат!$E$11) -> 299000 | ... AK36: =CHOOSE(AK4,Штат!$C$11,Штат!$D$11,Штат!$E$11) -> 923000
A37: Маркетинг | B37: =CHOOSE(B4,Допущения!$B$45,Допущения!$B$46,Допущения!$B$47) -> 150000 | C37: =CHOOSE(C4,Допущения!$B$45,Допущения!$B$46,Допущения!$B$47) -> 150000 | D37: =CHOOSE(D4,Допущения!$B$45,Допущения!$B$46,Допущения!$B$47) -> 150000 | E37: =CHOOSE(E4,Допущения!$B$45,Допущения!$B$46,Допущения!$B$47) -> 150000 | F37: =CHOOSE(F4,Допущения!$B$45,Допущения!$B$46,Допущения!$B$47) -> 150000 | G37: =CHOOSE(G4,Допущения!$B$45,Допущения!$B$46,Допущения!$B$47) -> 150000 | H37: =CHOOSE(H4,Допущения!$B$45,Допущения!$B$46,Допущения!$B$47) -> 150000 | I37: =CHOOSE(I4,Допущения!$B$45,Допущения!$B$46,Допущения!$B$47) -> 150000 | ... AK37: =CHOOSE(AK4,Допущения!$B$45,Допущения!$B$46,Допущения!$B$47) -> 400000
A38: Сервер, сервисы, прочее, взносы ИП | B38: =Допущения!$B$41+Допущения!$B$42+Допущения!$B$43+Допущения!$B$44 -> 55000 | C38: =Допущения!$B$41+Допущения!$B$42+Допущения!$B$43+Допущения!$B$44 -> 55000 | D38: =Допущения!$B$41+Допущения!$B$42+Допущения!$B$43+Допущения!$B$44 -> 55000 | E38: =Допущения!$B$41+Допущения!$B$42+Допущения!$B$43+Допущения!$B$44 -> 55000 | F38: =Допущения!$B$41+Допущения!$B$42+Допущения!$B$43+Допущения!$B$44 -> 55000 | G38: =Допущения!$B$41+Допущения!$B$42+Допущения!$B$43+Допущения!$B$44 -> 55000 | H38: =Допущения!$B$41+Допущения!$B$42+Допущения!$B$43+Допущения!$B$44 -> 55000 | I38: =Допущения!$B$41+Допущения!$B$42+Допущения!$B$43+Допущения!$B$44 -> 55000 | ... AK38: =Допущения!$B$41+Допущения!$B$42+Допущения!$B$43+Допущения!$B$44 -> 55000
A39: Расходы всего | B39: =SUM(B32:B38) -> 546985.35 | C39: =SUM(C32:C38) -> 553433.15 | D39: =SUM(D32:D38) -> 560848.13 | E39: =SUM(E32:E38) -> 569375.34 | F39: =SUM(F32:F38) -> 579181.65 | G39: =SUM(G32:G38) -> 590458.89 | H39: =SUM(H32:H38) -> 603427.73 | I39: =SUM(I32:I38) -> 618341.89 | ... AK39: =SUM(AK32:AK38) -> 1870653.4
A40: Прибыль (убыток) | B40: =B30-B39 -> -325270.35 | C40: =C30-C39 -> -298460.9 | D40: =D30-D39 -> -267630.04 | E40: =E30-E39 -> -232174.54 | F40: =F30-F39 -> -191400.73 | G40: =G30-G39 -> -144510.83 | H40: =H30-H39 -> -90587.459 | I40: =I30-I39 -> -28575.578 | ... AK40: =AK30-AK39 -> 1088642.5
A41: Накопленный результат | B41: =B40 -> -325270.35 | C41: =B41+C40 -> -623731.25 | D41: =C41+D40 -> -891361.29 | E41: =D41+E40 -> -1123535.8 | F41: =E41+F40 -> -1314936.6 | G41: =F41+G40 -> -1459447.4 | H41: =G41+H40 -> -1550034.9 | I41: =H41+I40 -> -1578610.4 | J41: =I41+J40 -> -1535872.3 | ... AK41: =AJ41+AK40 -> 11359785
...
